<!DOCTYPE html>
<html lang="en">
  <head>
    <meta charset="UTF-8" />
    <meta name="viewport" content="width=device-width, initial-scale=1.0" />
    <title>Document</title>
  </head>
  <body>
    <script>
      // new Promise((resolve, reject) => {
      //   return resolve('lalala');
      //   throw new Error('what the fuck 000');
      //   // return reject(new Error('what the fuck 000'));
      // })
      //   .then(res => {
      //     console.log(res);
      //     // throw new Error('what the fuck 111');
      //     return new Promise((resolve, reject) => {
      //       return reject(new Error('what the fuck 111'));
      //     });
      //   })
      //   .catch(err => console.log(err));

      // console.log('--------------------------------------');

      // new Promise((resolve, reject) => {
      //   return resolve('ok');
      // })
      //   .then(result => {
      //     console.log('result :>> ', result);
      //     blabla(); // 没有这个函数
      //   })
      //   .catch(err => console.log(err)); // ReferenceError: blabla is not defined
      // // 总结: catch不仅会捕获显式的rejection,还会捕获它上面的处理程序(handler)中意外出现的 error

      // console.log('--------------------------------------');
      // // 执行流：catch -> then
      // new Promise((resolve, reject) => {
      //   return reject(new Error('what the fuck 111!'));
      //   throw new Error('what the fuck 222!');//其实不执行
      // })
      //   .catch(error => {
      //     console.log('error :>> ', error);//测试
      //     // console.log('The error is handled, continue normally');
      //     return new Promise((resolve, reject) => {
      //       return resolve('The error is handled, continue normally');
      //     });
      //   })
      //   .then(result => {
      //     console.log('result :>> ', result);//测试
      //     console.log('Next successful handler runs');//测试
      //   });

      // console.log('--------------------------------------');

      // // 执行流：catch -> catch
      // new Promise((resolve, reject) => {
      //   return reject(new Error('what the fuck 111!')); //啰嗦版本
      //   // throw new Error('what the fuck 222!');//简洁版本
      // })
      //   .catch(error => {
      //     if (error instanceof URIError) {
      //       //处理它
      //     } else {
      //       //抛出错误
      //       console.log('error 000:>> ', error);
      //       //啰嗦版本
      //       return new Promise((resolve, reject) => {
      //         return reject(error);
      //       });
      //       //简洁版本
      //       // throw error; // 再次抛出此 error 或另外一个 error，执行将跳转至下一个 catch
      //     }
      //   })
      //   .then(res => {
      //     /* 这里根本不会运行 */
      //     console.log('res :>> ', res);
      //   })
      //   .catch(error => {
      //     console.log('error 001:>> ', error);
      //     // 不会返回任何内容 => 执行正常进行
      //   });

      // console.log('--------------------------------------');

      // new Promise(function (resolve, reject) {
      //   // noSuchFunction(); // 这里出现 error（没有这个函数）
      //   // return resolve('success');
      //   return reject('failure');
      // })
      //   .then(res => {
      //     // 一个或多个成功的 promise 处理程序（handler）
      //     console.log('res :>> ', res);
      //   })

      //   .catch(err => console.log('err :>> ', err));

      console.log('--------------------------------------');

      new Promise(function (resolve, reject) {
        return reject(new Error('What the fuck!'));
        throw new Error('What the fuck!');
      }); // 没有用来处理 error 的 catch

      window.addEventListener('unhandledrejection', event => {
        event.promise.catch(err => {
          console.log('err :>> ', err);
        });
        console.log('event :>> ', event);
        // 这个事件对象有两个特殊的属性：
        console.log('event.promise :>> ', event.promise); // [object Promise] - 生成该全局 error 的 promise
        console.log('event.reason :>> ', event.reason); // Error: Whoops! - 未处理的 error 对象
      });
    </script>
  </body>
</html>
